Workbook
Name BSAcctIDs: Drivers!$L$68:$L$103
Name BSAccts: Drivers!$D$68:$D$97
Name BSAcctType: Drivers!$K$68:$K$97
Name BSDriverAssumptions: Drivers!$F$68:$F$97
Name BSDrivers: Drivers!$E$68:$E$97
Name BSSections: Drivers!$G$68:$G$103
Name BSSectionsCF: Drivers!$J$68:$J$103
Name BSSummarys: Drivers!$H$68:$H$103
Name BSSummarysCF: Drivers!$I$68:$I$103
Name Company_Name: "Model Wiz Demo *"
Name dataGLBS: 'Data Summary'!$N$77:$AW$104
Name dataGLBSAcctIDs: 'Data Summary'!$J$77:$J$104
Name dataGLBSAccts: 'Data Summary'!$D$77:$D$104
Name dataGLBSCF: 'Data Summary'!$M$77:$AW$104
Name dataGLBSSections: 'Data Summary'!$E$77:$E$104
Name dataGLBSSummarys: 'Data Summary'!$F$77:$F$104
Name dataGLBSSummarysCF: 'Data Summary'!$I$77:$I$104
Name dataGLPL: 'Data Summary'!$N$42:$AW$74
Name dataGLPLAcctIDs: 'Data Summary'!$J$42:$J$74
Name dataGLPLAccts: 'Data Summary'!$D$42:$D$74
Name dataGLPLSections: 'Data Summary'!$E$42:$E$74
Name dataGLPLSummarys: 'Data Summary'!$F$42:$F$74
Name dataSummaryBS: 'Data Summary'!$N$28:$AW$38
Name dataSummaryBSAcctIDs: 'Data Summary'!$J$28:$J$38
Name dataSummaryBSAccts: 'Data Summary'!$D$28:$D$38
Name dataSummaryBSCF: 'Data Summary'!$M$28:$AW$38
Name dataSummaryBSSections: 'Data Summary'!$E$28:$E$38
Name dataSummaryBSSummarys: 'Data Summary'!$F$28:$F$38
Name dataSummaryPL: 'Data Summary'!$N$12:$AW$25
Name dataSummaryPLAcctIDs: 'Data Summary'!$J$12:$J$26
Name dataSummaryPLAccts: 'Data Summary'!$D$12:$D$26
Name dataSummaryPLSections: 'Data Summary'!$E$12:$E$25
Name dataSummaryPLSummarys: 'Data Summary'!$F$12:$F$25
Name Drivers_accountId: Drivers!$L:$L
Name Drivers_accountName: Drivers!$D:$D
Name Drivers_cashFlowSection: Drivers!$J:$J
Name Drivers_Driver: Drivers!$E:$E
Name Drivers_driverAccountType: Drivers!$K:$K
Name Drivers_DriverAssumption: Drivers!$F:$F
Name Drivers_driversSection: Drivers!$G:$G
Name Drivers_summaryGrouping: Drivers!$H:$H
Name DriversOwnersEquity: Drivers!$AI$97:$BS$103
Name endDates: 'Data Summary'!$N$5:$AW$5
Name endDatesCF: 'Data Summary'!$M$5:$AW$5
Name Error_Check: 'Error Check'!$D$12
Name Error_Range: 'Data Summary'!$M$107:$AW$124
Name Error_Range: Drivers!$P$106:$BS$116
Name Formats: _xlfn.ANCHORARRAY(Lists!$C$6)
Name LatestMonthOfActuals: 45930
Name Periods: _xlfn.ANCHORARRAY(Lists!$B$6)
Name PLAcctIDs: Drivers!$L$10:$L$66
Name PLAccts: Drivers!$D$10:$D$66
Name PLAcctType: Drivers!$K$10:$K$66
Name PLDriverAssumptions: Drivers!$F$10:$F$66
Name PLDrivers: Drivers!$E$10:$E$66
Name PLSections: Drivers!$G$10:$G$66
Name PLSummarys: Drivers!$H$10:$H$66
Name PLSummarysCF: Drivers!$J$10:$J$66
Name startDates: 'Data Summary'!$N$4:$AW$4
Name startDatesCF: 'Data Summary'!$M$4:$AW$4

Sheet Financial Statements
C2: Nimbus Cloud Solutions
C4: FINANCIAL STATEMENTS | E4: Last Quarter
E5: =B93 -> Q2 2025 | G5: ="vs. "&B97 -> vs. Q1 2025 | K5: ="vs. "&B100 -> vs. Q2 2024
E6: Selected Period | G6: Prior Period | H6: $ Var | I6: % Var | K6: Prior Year | L6: $ Var | M6: % Var
B8: PROFIT & LOSS
C10: Revenue | E10: {=SUMPRODUCT(('Data Summary'!$M$8:$AW$8>=$B$91)*('Data Summary'!$M$8:$AW$8<=$B$92)*'Data Summary'!M13:AW13)} -> 224373.97 | G10: {=SUMPRODUCT(('Data Summary'!$M$8:$AW$8>=$B$95)*('Data Summary'!$M$8:$AW$8<=$B$96)*'Data Summary'!M13:AW13)} -> 186307.22 | H10: =E10-G10 -> 38066.75 | I10: =IFERROR(E10/G10-1,0) -> 0.20432246 | K10: {=SUMPRODUCT(('Data Summary'!$M$8:$AW$8>=$B$98)*('Data Summary'!$M$8:$AW$8<=$B$99)*'Data Summary'!M13:AW13)} -> 143829 | L10: =E10-K10 -> 80544.97 | M10: =IFERROR(E10/K10-1,0) -> 0.56000508
C11: Total Revenue | E11: =E10 -> 224373.97 | G11: =G10 -> 186307.22 | H11: =E11-G11 -> 38066.75 | I11: =IFERROR(E11/G11-1,0) -> 0.20432246 | K11: =K10 -> 143829 | L11: =E11-K11 -> 80544.97 | M11: =IFERROR(E11/K11-1,0) -> 0.56000508
C13: Cost of Goods Sold | E13: {=SUMPRODUCT(('Data Summary'!$M$8:$AW$8>=$B$91)*('Data Summary'!$M$8:$AW$8<=$B$92)*('Data Summary'!M15:AW15+'Data Summary'!M16:AW16))} -> 20775.48 | G13: {=SUMPRODUCT(('Data Summary'!$M$8:$AW$8>=$B$95)*('Data Summary'!$M$8:$AW$8<=$B$96)*('Data Summary'!M15:AW15+'Data Summary'!M16:AW16))} -> 17685.42 | H13: =E13-G13 -> 3090.06 | I13: =IFERROR(E13/G13-1,0) -> 0.17472359 | K13: {=SUMPRODUCT(('Data Summary'!$M$8:$AW$8>=$B$98)*('Data Summary'!$M$8:$AW$8<=$B$99)*('Data Summary'!M15:AW15+'Data Summary'!M16:AW16))} -> 12551.5 | L13: =E13-K13 -> 8223.98 | M13: =IFERROR(E13/K13-1,0) -> 0.6552189
C14: Gross Profit | E14: =E11-E13 -> 203598.49 | G14: =G11-G13 -> 168621.8 | H14: =E14-G14 -> 34976.69 | I14: =IFERROR(E14/G14-1,0) -> 0.20742686 | K14: =K11-K13 -> 131277.5 | L14: =E14-K14 -> 72320.99 | M14: =IFERROR(E14/K14-1,0) -> 0.55090164
C16: Marketing & Advertising | E16: {=SUMPRODUCT(('Data Summary'!$M$8:$AW$8>=$B$91)*('Data Summary'!$M$8:$AW$8<=$B$92)*'Data Summary'!M17:AW17)} -> 226320.72 | G16: {=SUMPRODUCT(('Data Summary'!$M$8:$AW$8>=$B$95)*('Data Summary'!$M$8:$AW$8<=$B$96)*'Data Summary'!M17:AW17)} -> 195505.87 | H16: =E16-G16 -> 30814.85 | I16: =IFERROR(E16/G16-1,0) -> 0.15761598 | K16: {=SUMPRODUCT(('Data Summary'!$M$8:$AW$8>=$B$98)*('Data Summary'!$M$8:$AW$8<=$B$99)*'Data Summary'!M17:AW17)} -> 125723 | L16: =E16-K16 -> 100597.72 | M16: =IFERROR(E16/K16-1,0) -> 0.80015367
C17: Office & Other G&A | E17: {=SUMPRODUCT(('Data Summary'!$M$8:$AW$8>=$B$91)*('Data Summary'!$M$8:$AW$8<=$B$92)*'Data Summary'!M18:AW18)} -> 224926.82 | G17: {=SUMPRODUCT(('Data Summary'!$M$8:$AW$8>=$B$95)*('Data Summary'!$M$8:$AW$8<=$B$96)*'Data Summary'!M18:AW18)} -> 193436.37 | H17: =E17-G17 -> 31490.45 | I17: =IFERROR(E17/G17-1,0) -> 0.16279488 | K17: {=SUMPRODUCT(('Data Summary'!$M$8:$AW$8>=$B$98)*('Data Summary'!$M$8:$AW$8<=$B$99)*'Data Summary'!M18:AW18)} -> 132220.5 | L17: =E17-K17 -> 92706.32 | M17: =IFERROR(E17/K17-1,0) -> 0.70114937
C18: Payroll | E18: {=SUMPRODUCT(('Data Summary'!$M$8:$AW$8>=$B$91)*('Data Summary'!$M$8:$AW$8<=$B$92)*'Data Summary'!M19:AW19)} -> 201582.84 | G18: {=SUMPRODUCT(('Data Summary'!$M$8:$AW$8>=$B$95)*('Data Summary'!$M$8:$AW$8<=$B$96)*'Data Summary'!M19:AW19)} -> 174134.87 | H18: =E18-G18 -> 27447.97 | I18: =IFERROR(E18/G18-1,0) -> 0.15762478 | K18: {=SUMPRODUCT(('Data Summary'!$M$8:$AW$8>=$B$98)*('Data Summary'!$M$8:$AW$8<=$B$99)*'Data Summary'!M19:AW19)} -> 108961 | L18: =E18-K18 -> 92621.84 | M18: =IFERROR(E18/K18-1,0) -> 0.8500458
C19: Professional Services | E19: {=SUMPRODUCT(('Data Summary'!$M$8:$AW$8>=$B$91)*('Data Summary'!$M$8:$AW$8<=$B$92)*'Data Summary'!M20:AW20)} -> 72600 | G19: {=SUMPRODUCT(('Data Summary'!$M$8:$AW$8>=$B$95)*('Data Summary'!$M$8:$AW$8<=$B$96)*'Data Summary'!M20:AW20)} -> 62714.72 | H19: =E19-G19 -> 9885.28 | I19: =IFERROR(E19/G19-1,0) -> 0.15762296 | K19: {=SUMPRODUCT(('Data Summary'!$M$8:$AW$8>=$B$98)*('Data Summary'!$M$8:$AW$8<=$B$99)*'Data Summary'!M20:AW20)} -> 39437 | L19: =E19-K19 -> 33163 | M19: =IFERROR(E19/K19-1,0) -> 0.84091082
C20: Travel & Entertainment | E20: {=SUMPRODUCT(('Data Summary'!$M$8:$AW$8>=$B$91)*('Data Summary'!$M$8:$AW$8<=$B$92)*'Data Summary'!M21:AW21)} -> 24456.9 | G20: {=SUMPRODUCT(('Data Summary'!$M$8:$AW$8>=$B$95)*('Data Summary'!$M$8:$AW$8<=$B$96)*'Data Summary'!M21:AW21)} -> 21125.46 | H20: =E20-G20 -> 3331.44 | I20: =IFERROR(E20/G20-1,0) -> 0.15769787 | K20: {=SUMPRODUCT(('Data Summary'!$M$8:$AW$8>=$B$98)*('Data Summary'!$M$8:$AW$8<=$B$99)*'Data Summary'!M21:AW21)} -> 13593 | L20: =E20-K20 -> 10863.9 | M20: =IFERROR(E20/K20-1,0) -> 0.79922754
C21: Total Operating Expenses | E21: =SUM(E16:E20) -> 749887.28 | G21: =SUM(G16:G20) -> 646917.29 | H21: =E21-G21 -> 102969.99 | I21: =IFERROR(E21/G21-1,0) -> 0.15917025 | K21: =SUM(K16:K20) -> 419934.5 | L21: =E21-K21 -> 329952.78 | M21: =IFERROR(E21/K21-1,0) -> 0.78572439
C23: Operating Income (Loss) | E23: =E14-E21 -> -546288.79 | G23: =G14-G21 -> -478295.49 | H23: =E23-G23 -> -67993.3 | I23: =IFERROR(E23/G23-1,0) -> 0.14215752 | K23: =K14-K21 -> -288657 | L23: =E23-K23 -> -257631.79 | M23: =IFERROR(E23/K23-1,0) -> 0.89251877
C25: Other Income | E25: {=SUMPRODUCT(('Data Summary'!$M$8:$AW$8>=$B$91)*('Data Summary'!$M$8:$AW$8<=$B$92)*'Data Summary'!M22:AW22)} -> 0 | G25: {=SUMPRODUCT(('Data Summary'!$M$8:$AW$8>=$B$95)*('Data Summary'!$M$8:$AW$8<=$B$96)*'Data Summary'!M22:AW22)} -> 0 | H25: =E25-G25 -> 0 | I25: =IFERROR(E25/G25-1,0) -> 0 | K25: {=SUMPRODUCT(('Data Summary'!$M$8:$AW$8>=$B$98)*('Data Summary'!$M$8:$AW$8<=$B$99)*'Data Summary'!M22:AW22)} -> 0 | L25: =E25-K25 -> 0 | M25: =IFERROR(E25/K25-1,0) -> 0
C26: Depreciation & Amortization | E26: {=SUMPRODUCT(('Data Summary'!$M$8:$AW$8>=$B$91)*('Data Summary'!$M$8:$AW$8<=$B$92)*'Data Summary'!M23:AW23)} -> 0 | G26: {=SUMPRODUCT(('Data Summary'!$M$8:$AW$8>=$B$95)*('Data Summary'!$M$8:$AW$8<=$B$96)*'Data Summary'!M23:AW23)} -> 0 | H26: =E26-G26 -> 0 | I26: =IFERROR(E26/G26-1,0) -> 0 | K26: {=SUMPRODUCT(('Data Summary'!$M$8:$AW$8>=$B$98)*('Data Summary'!$M$8:$AW$8<=$B$99)*'Data Summary'!M23:AW23)} -> 0 | L26: =E26-K26 -> 0 | M26: =IFERROR(E26/K26-1,0) -> 0
C27: Other Expenses | E27: {=SUMPRODUCT(('Data Summary'!$M$8:$AW$8>=$B$91)*('Data Summary'!$M$8:$AW$8<=$B$92)*('Data Summary'!M24:AW24+'Data Summary'!M25:AW25))} -> 64486.74 | G27: {=SUMPRODUCT(('Data Summary'!$M$8:$AW$8>=$B$95)*('Data Summary'!$M$8:$AW$8<=$B$96)*('Data Summary'!M24:AW24+'Data Summary'!M25:AW25))} -> 64486.74 | H27: =E27-G27 -> 0 | I27: =IFERROR(E27/G27-1,0) -> -1.110223e-16 | K27: {=SUMPRODUCT(('Data Summary'!$M$8:$AW$8>=$B$98)*('Data Summary'!$M$8:$AW$8<=$B$99)*('Data Summary'!M24:AW24+'Data Summary'!M25:AW25))} -> 64488 | L27: =E27-K27 -> -1.26 | M27: =IFERROR(E27/K27-1,0) -> -1.9538519e-05
C29: Net Income (Loss) | E29: =E23+E25-E26-E27 -> -610775.53 | G29: =G23+G25-G26-G27 -> -542782.23 | H29: =E29-G29 -> -67993.3 | I29: =IFERROR(E29/G29-1,0) -> 0.1252681 | K29: =K23+K25-K26-K27 -> -353145 | L29: =E29-K29 -> -257630.53 | M29: =IFERROR(E29/K29-1,0) -> 0.72953186
B32: BALANCE SHEET
C34: Assets
C35: Cash | E35: =INDEX('Data Summary'!M29:AW29,MATCH($B$92,'Data Summary'!$M$8:$AW$8,0)) -> 1594040.1 | G35: =INDEX('Data Summary'!M29:AW29,MATCH($B$96,'Data Summary'!$M$8:$AW$8,0)) -> 2207358.5 | H35: =E35-G35 -> -613318.33 | I35: =IFERROR(E35/G35-1,0) -> -0.27785171 | K35: =INDEX('Data Summary'!M29:AW29,MATCH($B$99,'Data Summary'!$M$8:$AW$8,0)) -> 3656851.5 | L35: =E35-K35 -> -2062811.4 | M35: =IFERROR(E35/K35-1,0) -> -0.56409492
C36: Accounts Receivable | E36: =INDEX('Data Summary'!M28:AW28,MATCH($B$92,'Data Summary'!$M$8:$AW$8,0)) -> 69302.55 | G36: =INDEX('Data Summary'!M28:AW28,MATCH($B$96,'Data Summary'!$M$8:$AW$8,0)) -> 56307.77 | H36: =E36-G36 -> 12994.78 | I36: =IFERROR(E36/G36-1,0) -> 0.23078129 | K36: =INDEX('Data Summary'!M28:AW28,MATCH($B$99,'Data Summary'!$M$8:$AW$8,0)) -> 44983 | L36: =E36-K36 -> 24319.55 | M36: =IFERROR(E36/K36-1,0) -> 0.54063869
C37: Current Assets | E37: =INDEX('Data Summary'!M30:AW30,MATCH($B$92,'Data Summary'!$M$8:$AW$8,0)) -> 25819.5 | G37: =INDEX('Data Summary'!M30:AW30,MATCH($B$96,'Data Summary'!$M$8:$AW$8,0)) -> 26119.5 | H37: =E37-G37 -> -300 | I37: =IFERROR(E37/G37-1,0) -> -0.011485672 | K37: =INDEX('Data Summary'!M30:AW30,MATCH($B$99,'Data Summary'!$M$8:$AW$8,0)) -> 26119.5 | L37: =E37-K37 -> -300 | M37: =IFERROR(E37/K37-1,0) -> -0.011485672
C38: Fixed Assets | E38: =INDEX('Data Summary'!M31:AW31,MATCH($B$92,'Data Summary'!$M$8:$AW$8,0)) -> 48553.54 | G38: =INDEX('Data Summary'!M31:AW31,MATCH($B$96,'Data Summary'!$M$8:$AW$8,0)) -> 57705.52 | H38: =E38-G38 -> -9151.98 | I38: =IFERROR(E38/G38-1,0) -> -0.158598 | K38: =INDEX('Data Summary'!M31:AW31,MATCH($B$99,'Data Summary'!$M$8:$AW$8,0)) -> 85163 | L38: =E38-K38 -> -36609.46 | M38: =IFERROR(E38/K38-1,0) -> -0.42987518
C39: Other Current Assets | E39: =INDEX('Data Summary'!M32:AW32,MATCH($B$92,'Data Summary'!$M$8:$AW$8,0)) -> 0 | G39: =INDEX('Data Summary'!M32:AW32,MATCH($B$96,'Data Summary'!$M$8:$AW$8,0)) -> 0 | H39: =E39-G39 -> 0 | I39: =IFERROR(E39/G39-1,0) -> 0 | K39: =INDEX('Data Summary'!M32:AW32,MATCH($B$99,'Data Summary'!$M$8:$AW$8,0)) -> 0 | L39: =E39-K39 -> 0 | M39: =IFERROR(E39/K39-1,0) -> 0
C40: Total Assets | E40: =SUM(E35:E39) -> 1737715.7 | G40: =SUM(G35:G39) -> 2347491.3 | H40: =E40-G40 -> -609775.53 | I40: =IFERROR(E40/G40-1,0) -> -0.25975625 | K40: =SUM(K35:K39) -> 3813117 | L40: =E40-K40 -> -2075401.3 | M40: =IFERROR(E40/K40-1,0) -> -0.54427946
H41: =E41-G41 -> 0 | I41: =IFERROR(E41/G41-1,0) -> 0 | L41: =E41-K41 -> 0 | M41: =IFERROR(E41/K41-1,0) -> 0
C42: Liabilities | H42: =E42-G42 -> 0 | I42: =IFERROR(E42/G42-1,0) -> 0 | L42: =E42-K42 -> 0 | M42: =IFERROR(E42/K42-1,0) -> 0
C43: Accounts Payable | E43: =INDEX('Data Summary'!M33:AW33,MATCH($B$92,'Data Summary'!$M$8:$AW$8,0)) -> 56349.5 | G43: =INDEX('Data Summary'!M33:AW33,MATCH($B$96,'Data Summary'!$M$8:$AW$8,0)) -> 55349.5 | H43: =E43-G43 -> 1000 | I43: =IFERROR(E43/G43-1,0) -> 0.018067011 | K43: =INDEX('Data Summary'!M33:AW33,MATCH($B$99,'Data Summary'!$M$8:$AW$8,0)) -> 55349.5 | L43: =E43-K43 -> 1000 | M43: =IFERROR(E43/K43-1,0) -> 0.018067011
C44: Current Liabilities | E44: =INDEX('Data Summary'!M34:AW34,MATCH($B$92,'Data Summary'!$M$8:$AW$8,0)) -> -4942 | G44: =INDEX('Data Summary'!M34:AW34,MATCH($B$96,'Data Summary'!$M$8:$AW$8,0)) -> -4942 | H44: =E44-G44 -> 0 | I44: =IFERROR(E44/G44-1,0) -> 0 | K44: =INDEX('Data Summary'!M34:AW34,MATCH($B$99,'Data Summary'!$M$8:$AW$8,0)) -> -4942 | L44: =E44-K44 -> 0 | M44: =IFERROR(E44/K44-1,0) -> 0
C45: Debt | E45: =INDEX('Data Summary'!M35:AW35,MATCH($B$92,'Data Summary'!$M$8:$AW$8,0)) -> 1530000 | G45: =INDEX('Data Summary'!M35:AW35,MATCH($B$96,'Data Summary'!$M$8:$AW$8,0)) -> 1530000 | H45: =E45-G45 -> 0 | I45: =IFERROR(E45/G45-1,0) -> 0 | K45: =INDEX('Data Summary'!M35:AW35,MATCH($B$99,'Data Summary'!$M$8:$AW$8,0)) -> 1530000 | L45: =E45-K45 -> 0 | M45: =IFERROR(E45/K45-1,0) -> 0
C46: Deferred Revenue | E46: =INDEX('Data Summary'!M36:AW36,MATCH($B$92,'Data Summary'!$M$8:$AW$8,0)) -> 23270 | G46: =INDEX('Data Summary'!M36:AW36,MATCH($B$96,'Data Summary'!$M$8:$AW$8,0)) -> 23270 | H46: =E46-G46 -> 0 | I46: =IFERROR(E46/G46-1,0) -> 0 | K46: =INDEX('Data Summary'!M36:AW36,MATCH($B$99,'Data Summary'!$M$8:$AW$8,0)) -> 23270 | L46: =E46-K46 -> 0 | M46: =IFERROR(E46/K46-1,0) -> 0
C47: Total Liabilities | E47: =SUM(E43:E46) -> 1604677.5 | G47: =SUM(G43:G46) -> 1603677.5 | H47: =E47-G47 -> 1000 | I47: =IFERROR(E47/G47-1,0) -> 0.00062356677 | K47: =SUM(K43:K46) -> 1603677.5 | L47: =E47-K47 -> 1000 | M47: =IFERROR(E47/K47-1,0) -> 0.00062356677
H48: =E48-G48 -> 0 | I48: =IFERROR(E48/G48-1,0) -> 0 | L48: =E48-K48 -> 0 | M48: =IFERROR(E48/K48-1,0) -> 0
C49: Equity | H49: =E49-G49 -> 0 | I49: =IFERROR(E49/G49-1,0) -> 0 | L49: =E49-K49 -> 0 | M49: =IFERROR(E49/K49-1,0) -> 0
C50: Contributed Capital | E50: =INDEX('Data Summary'!M37:AW37,MATCH($B$92,'Data Summary'!$M$8:$AW$8,0)) -> 3500000 | G50: =INDEX('Data Summary'!M37:AW37,MATCH($B$96,'Data Summary'!$M$8:$AW$8,0)) -> 3500000 | H50: =E50-G50 -> 0 | I50: =IFERROR(E50/G50-1,0) -> 0 | K50: =INDEX('Data Summary'!M37:AW37,MATCH($B$99,'Data Summary'!$M$8:$AW$8,0)) -> 3500000 | L50: =E50-K50 -> 0 | M50: =IFERROR(E50/K50-1,0) -> 0
C51: Retained Earnings | E51: =INDEX('Data Summary'!M38:AW38,MATCH($B$92,'Data Summary'!$M$8:$AW$8,0)) -> -3366961.8 | G51: =INDEX('Data Summary'!M38:AW38,MATCH($B$96,'Data Summary'!$M$8:$AW$8,0)) -> -2756186.2 | H51: =E51-G51 -> -610775.53 | I51: =IFERROR(E51/G51-1,0) -> 0.22160169 | K51: =INDEX('Data Summary'!M38:AW38,MATCH($B$99,'Data Summary'!$M$8:$AW$8,0)) -> -1290560.5 | L51: =E51-K51 -> -2076401.3 | M51: =IFERROR(E51/K51-1,0) -> 1.6089143
C52: Total Equity | E52: =E50+E51 -> 133038.24 | G52: =G50+G51 -> 743813.77 | H52: =E52-G52 -> -610775.53 | I52: =IFERROR(E52/G52-1,0) -> -0.82114039 | K52: =K50+K51 -> 2209439.5 | L52: =E52-K52 -> -2076401.3 | M52: =IFERROR(E52/K52-1,0) -> -0.93978643
...

Sheet AR Command Center
B2: ◼ ◼ | D2: AR AGING COMMAND CENTER | K2: As of: May 11, 2026
B5: TOTAL AR OUTSTANDING | D5: CURRENT DSO | F5: % PAST DUE | H5: # OPEN INVOICES
B6: =SUMIF('AR Data'!J2:J35,"<>Paid",'AR Data'!G2:G35) -> 5495500 | D6: ='AR Data'!P14 -> 227.4 | F6: =SUMIF('AR Data'!J2:J35,"Past Due",'AR Data'!G2:G35)/SUMIF('AR Data'!J2:J35,"<>Paid",'AR Data'!G2:G35) -> 1 | H6: =COUNTIF('AR Data'!J2:J35,"<>Paid") -> 30
B7: All unpaid invoices | D7: Days Sales Outstanding | F7: AR beyond 30 days | H7: Outstanding invoices
B36: AGING BUCKETS | I36: DSO TREND (12-MONTH)
C37: Bucket | D37: Amount | E37: # Invoices | F37: % of Total | G37: Avg Days Out | I37: Month | J37: DSO | K37: Target
C38: Current (0-30) | D38: =SUMIFS('AR Data'!G2:G35,'AR Data'!I2:I35,"Current") -> 0 | E38: =COUNTIFS('AR Data'!I2:I35,"Current") -> 0 | F38: =IF(D42=0,0,D38/D42) -> 0 | G38: =IFERROR(AVERAGEIFS('AR Data'!H2:H35,'AR Data'!I2:I35,"Current"),0) -> 0 | I38: ='AR Data'!M3 -> Jun-25 | J38: ='AR Data'!P3 -> 124.81752 | K38: 45
C39: 31-60 Days | D39: =SUMIFS('AR Data'!G2:G35,'AR Data'!I2:I35,"31-60") -> 2689000 | E39: =COUNTIFS('AR Data'!I2:I35,"31-60") -> 12 | F39: =IF(D42=0,0,D39/D42) -> 0.48930943 | G39: =IFERROR(AVERAGEIFS('AR Data'!H2:H35,'AR Data'!I2:I35,"31-60"),0) -> 43.166667 | I39: ='AR Data'!M4 -> Jul-25 | J39: ='AR Data'!P4 -> 123.38028 | K39: 45
C40: 61-90 Days | D40: =SUMIFS('AR Data'!G2:G35,'AR Data'!I2:I35,"61-90") -> 1351500 | E40: =COUNTIFS('AR Data'!I2:I35,"61-90") -> 7 | F40: =IF(D42=0,0,D40/D42) -> 0.24592849 | G40: =IFERROR(AVERAGEIFS('AR Data'!H2:H35,'AR Data'!I2:I35,"61-90"),0) -> 71.571429 | I40: ='AR Data'!M5 -> Aug-25 | J40: ='AR Data'!P5 -> 131.25 | K40: 45
C41: 90+ Days | D41: =SUMIFS('AR Data'!G2:G35,'AR Data'!I2:I35,"90+") -> 1455000 | E41: =COUNTIFS('AR Data'!I2:I35,"90+") -> 11 | F41: =IF(D42=0,0,D41/D42) -> 0.26476208 | G41: =IFERROR(AVERAGEIFS('AR Data'!H2:H35,'AR Data'!I2:I35,"90+"),0) -> 229.36364 | I41: ='AR Data'!M6 -> Sep-25 | J41: ='AR Data'!P6 -> 145.89928 | K41: 45
C42: TOTAL | D42: =SUM(D38:D41) -> 5495500 | E42: =SUM(E38:E41) -> 30 | F42: =SUM(F38:F41) -> 1 | G42: =IFERROR(AVERAGEIFS('AR Data'!H2:H35,'AR Data'!J2:J35,"<>Paid"),0) -> 118.06667 | I42: ='AR Data'!M7 -> Oct-25 | J42: ='AR Data'!P7 -> 125.34247 | K42: 45
I43: ='AR Data'!M8 -> Nov-25 | J43: ='AR Data'!P8 -> 129.26174 | K43: 45
B44: CUSTOMER CONCENTRATION | I44: ='AR Data'!M9 -> Dec-25 | J44: ='AR Data'!P9 -> 139.73684 | K44: 45
B45: Customer | C45: AR Balance | D45: % of Total | E45: Risk | I45: ='AR Data'!M10 -> Jan-26 | J45: ='AR Data'!P10 -> 157.71429 | K45: 45
B46: GlobalTech Solutions | C46: =SUMIFS('AR Data'!G2:G35,'AR Data'!B2:B35,B46,'AR Data'!J2:J35,"<>Paid") -> 665000 | D46: =IF($C$59=0,0,C46/$C$59) -> 0.1210081 | E46: =IF(D46>=0.15,"⚠ High",IF(D46>=0.1,"Medium","Low")) -> Medium | I46: ='AR Data'!M11 -> Feb-26 | J46: ='AR Data'!P11 -> 148.69565 | K46: 45
B47: Ironclad Manufacturing | C47: =SUMIFS('AR Data'!G2:G35,'AR Data'!B2:B35,B47,'AR Data'!J2:J35,"<>Paid") -> 912000 | D47: =IF($C$59=0,0,C47/$C$59) -> 0.16595396 | E47: =IF(D47>=0.15,"⚠ High",IF(D47>=0.1,"Medium","Low")) -> ⚠ High | I47: ='AR Data'!M12 -> Mar-26 | J47: ='AR Data'!P12 -> 157.34266 | K47: 45
B48: Cascade Industries | C48: =SUMIFS('AR Data'!G2:G35,'AR Data'!B2:B35,B48,'AR Data'!J2:J35,"<>Paid") -> 698000 | D48: =IF($C$59=0,0,C48/$C$59) -> 0.12701301 | E48: =IF(D48>=0.15,"⚠ High",IF(D48>=0.1,"Medium","Low")) -> Medium | I48: ='AR Data'!M13 -> Apr-26 | J48: ='AR Data'!P13 -> 157.7027 | K48: 45
B49: Apex Technologies | C49: =SUMIFS('AR Data'!G2:G35,'AR Data'!B2:B35,B49,'AR Data'!J2:J35,"<>Paid") -> 594500 | D49: =IF($C$59=0,0,C49/$C$59) -> 0.10817942 | E49: =IF(D49>=0.15,"⚠ High",IF(D49>=0.1,"Medium","Low")) -> Medium | I49: ='AR Data'!M14 -> May-26 | J49: ='AR Data'!P14 -> 227.4 | K49: 45
B50: Evergreen Health | C50: =SUMIFS('AR Data'!G2:G35,'AR Data'!B2:B35,B50,'AR Data'!J2:J35,"<>Paid") -> 575000 | D50: =IF($C$59=0,0,C50/$C$59) -> 0.10463106 | E50: =IF(D50>=0.15,"⚠ High",IF(D50>=0.1,"Medium","Low")) -> Medium
B51: Luminary Brands | C51: =SUMIFS('AR Data'!G2:G35,'AR Data'!B2:B35,B51,'AR Data'!J2:J35,"<>Paid") -> 495000 | D51: =IF($C$59=0,0,C51/$C$59) -> 0.090073697 | E51: =IF(D51>=0.15,"⚠ High",IF(D51>=0.1,"Medium","Low")) -> Low | I51: ⚠ TOP PAST DUE INVOICES
B52: Nexus Consulting | C52: =SUMIFS('AR Data'!G2:G35,'AR Data'!B2:B35,B52,'AR Data'!J2:J35,"<>Paid") -> 360000 | D52: =IF($C$59=0,0,C52/$C$59) -> 0.065508143 | E52: =IF(D52>=0.15,"⚠ High",IF(D52>=0.1,"Medium","Low")) -> Low | I52: Invoice | J52: Customer | K52: Balance
B53: BlueStar Logistics | C53: =SUMIFS('AR Data'!G2:G35,'AR Data'!B2:B35,B53,'AR Data'!J2:J35,"<>Paid") -> 266000 | D53: =IF($C$59=0,0,C53/$C$59) -> 0.048403239 | E53: =IF(D53>=0.15,"⚠ High",IF(D53>=0.1,"Medium","Low")) -> Low | I53: {=IFERROR(INDEX('AR Data'!A2:A35,MATCH(LARGE(IF('AR Data'!J2:J35="Past Due",'AR Data'!G2:G35),1),'AR Data'!G2:G35,0)),"")} -> INV-1017 | J53: {=IFERROR(INDEX('AR Data'!B2:B35,MATCH(LARGE(IF('AR Data'!J2:J35="Past Due",'AR Data'!G2:G35),1),'AR Data'!G2:G35,0)),"")} -> GlobalTech Solutions | K53: {=IFERROR(LARGE(IF('AR Data'!J2:J35="Past Due",'AR Data'!G2:G35),1),"")} -> 520000
B54: Jetstream Aviation | C54: =SUMIFS('AR Data'!G2:G35,'AR Data'!B2:B35,B54,'AR Data'!J2:J35,"<>Paid") -> 279000 | D54: =IF($C$59=0,0,C54/$C$59) -> 0.050768811 | E54: =IF(D54>=0.15,"⚠ High",IF(D54>=0.1,"Medium","Low")) -> Low | I54: {=IFERROR(INDEX('AR Data'!A2:A35,MATCH(LARGE(IF('AR Data'!J2:J35="Past Due",'AR Data'!G2:G35),2),'AR Data'!G2:G35,0)),"")} -> INV-1022 | J54: {=IFERROR(INDEX('AR Data'!B2:B35,MATCH(LARGE(IF('AR Data'!J2:J35="Past Due",'AR Data'!G2:G35),2),'AR Data'!G2:G35,0)),"")} -> Ironclad Manufacturing | K54: {=IFERROR(LARGE(IF('AR Data'!J2:J35="Past Due",'AR Data'!G2:G35),2),"")} -> 445000
B55: Delta Partners | C55: =SUMIFS('AR Data'!G2:G35,'AR Data'!B2:B35,B55,'AR Data'!J2:J35,"<>Paid") -> 201500 | D55: =IF($C$59=0,0,C55/$C$59) -> 0.036666363 | E55: =IF(D55>=0.15,"⚠ High",IF(D55>=0.1,"Medium","Low")) -> Low | I55: {=IFERROR(INDEX('AR Data'!A2:A35,MATCH(LARGE(IF('AR Data'!J2:J35="Past Due",'AR Data'!G2:G35),3),'AR Data'!G2:G35,0)),"")} -> INV-1007 | J55: {=IFERROR(INDEX('AR Data'!B2:B35,MATCH(LARGE(IF('AR Data'!J2:J35="Past Due",'AR Data'!G2:G35),3),'AR Data'!G2:G35,0)),"")} -> Cascade Industries | K55: {=IFERROR(LARGE(IF('AR Data'!J2:J35="Past Due",'AR Data'!G2:G35),3),"")} -> 425000
B56: Harbor Financial | C56: =SUMIFS('AR Data'!G2:G35,'AR Data'!B2:B35,B56,'AR Data'!J2:J35,"<>Paid") -> 198000 | D56: =IF($C$59=0,0,C56/$C$59) -> 0.036029479 | E56: =IF(D56>=0.15,"⚠ High",IF(D56>=0.1,"Medium","Low")) -> Low | I56: {=IFERROR(INDEX('AR Data'!A2:A35,MATCH(LARGE(IF('AR Data'!J2:J35="Past Due",'AR Data'!G2:G35),4),'AR Data'!G2:G35,0)),"")} -> INV-1023 | J56: {=IFERROR(INDEX('AR Data'!B2:B35,MATCH(LARGE(IF('AR Data'!J2:J35="Past Due",'AR Data'!G2:G35),4),'AR Data'!G2:G35,0)),"")} -> Ironclad Manufacturing | K56: {=IFERROR(LARGE(IF('AR Data'!J2:J35="Past Due",'AR Data'!G2:G35),4),"")} -> 367000
B57: KeyPoint Analytics | C57: =SUMIFS('AR Data'!G2:G35,'AR Data'!B2:B35,B57,'AR Data'!J2:J35,"<>Paid") -> 173500 | D57: =IF($C$59=0,0,C57/$C$59) -> 0.031571286 | E57: =IF(D57>=0.15,"⚠ High",IF(D57>=0.1,"Medium","Low")) -> Low | I57: {=IFERROR(INDEX('AR Data'!A2:A35,MATCH(LARGE(IF('AR Data'!J2:J35="Past Due",'AR Data'!G2:G35),5),'AR Data'!G2:G35,0)),"")} -> INV-1012 | J57: {=IFERROR(INDEX('AR Data'!B2:B35,MATCH(LARGE(IF('AR Data'!J2:J35="Past Due",'AR Data'!G2:G35),5),'AR Data'!G2:G35,0)),"")} -> Evergreen Health | K57: {=IFERROR(LARGE(IF('AR Data'!J2:J35="Past Due",'AR Data'!G2:G35),5),"")} -> 298000
B58: Frontier Software | C58: =SUMIFS('AR Data'!G2:G35,'AR Data'!B2:B35,B58,'AR Data'!J2:J35,"<>Paid") -> 78000 | D58: =IF($C$59=0,0,C58/$C$59) -> 0.014193431 | E58: =IF(D58>=0.15,"⚠ High",IF(D58>=0.1,"Medium","Low")) -> Low
B59: TOTAL | C59: =SUM(C46:C58) -> 5495500 | D59: =SUM(D46:D58) -> 1 | E59: =IF(D59>=0.15,"⚠ High",IF(D59>=0.1,"Medium","Low")) -> ⚠ High | I59: Top 3 Concentration: | J59: {=SUMPRODUCT(LARGE(C46:C58,{1,2,3}))/C59} -> 0.41397507
I60: Top 5 Concentration: | J60: {=SUMPRODUCT(LARGE(C46:C58,{1,2,3,4,5}))/C59} -> 0.62678555
I61: HHI Index: | J61: {=SUMPRODUCT((C46:C58/C59)^2)*10000} -> 1021.3211

Sheet KPI Dashboard
B2: ◼ ◼ | C2: Nimbus Cloud Solutions | O2: ="As of: "&TEXT(TODAY(),"MMM DD, YYYY") -> As of: Jun 05, 2026
B4: KPI DASHBOARD | O4: ="Latest Actuals: "&TEXT('Data Summary'!AH8,"MMM YYYY") -> Latest Actuals: Sep 2025
C6: REVENUE (LTM) | D6: COGS (LTM) | E6: GROSS MARGIN (LTM) | F6: NET INCOME (LTM) | H6: CASH BALANCE | I6: ACCOUNTS RECEIVABLE | J6: TOTAL OPEX (LTM) | K6: DEBT BALANCE | M6: MONTHLY BURN RATE | N6: CASH RUNWAY (MONTHS)
C7: {=SUMPRODUCT(('Data Summary'!M3:AW3="Actual")*'Data Summary'!M13:AW13)} -> 1294745.6 | D7: {=SUMPRODUCT(('Data Summary'!M3:AW3="Actual")*'Data Summary'!M15:AW15)} -> 118232.14 | E7: =IFERROR(1-D7/C7, 0) -> 0.90868311 | F7: {=C7-D7-SUMPRODUCT(('Data Summary'!M3:AW3="Actual")*(('Data Summary'!M17:AW17+'Data Summary'!M18:AW18+'Data Summary'!M19:AW19+'Data Summary'!M20:AW20+'Data Summary'!M21:AW21)))} -> -3062766.8 | H7: ='Data Summary'!AH29 -> 893122.77 | I7: ='Data Summary'!AH28 -> 73923.66 | J7: {=SUMPRODUCT(('Data Summary'!M3:AW3="Actual")*(('Data Summary'!M17:AW17+'Data Summary'!M18:AW18+'Data Summary'!M19:AW19+'Data Summary'!M20:AW20+'Data Summary'!M21:AW21)))} -> 4239280.2 | K7: ='Data Summary'!AH35 -> 1530000 | M7: =D11-C11 -> 215869.64 | N7: =IFERROR(ROUND(H7/M7,1),"N/A") -> 4.1
C8: Cumulative Actual Period | D8: Cumulative Actual Period | E8: Revenue less COGS | F8: Revenue less all expenses | H8: Latest actual month | I8: Latest actual month | J8: Cumulative Actual Period | K8: Latest actual month | M8: Opex minus Revenue | N8: Cash ÷ Monthly Burn
C10: MONTHLY REVENUE | D10: MONTHLY OPEX | E10: PAYROLL | F10: MARKETING & ADVERTISING | H10: PROF. SERVICES | I10: OFFICE & G&A | J10: TRAVEL & ENTERTAINMENT | K10: OTHER EXPENSES | M10: COGS % OF REVENUE | N10: OPEX % OF REVENUE
C11: ='Data Summary'!AH13 -> 87314.98 | D11: ='Data Summary'!AH17+'Data Summary'!AH18+'Data Summary'!AH19+'Data Summary'!AH20+'Data Summary'!AH21 -> 303184.62 | E11: ='Data Summary'!AH19 -> 81610 | F11: ='Data Summary'!AH17 -> 91625.69 | H11: ='Data Summary'!AH20 -> 29392.09 | I11: ='Data Summary'!AH18 -> 90655.73 | J11: ='Data Summary'!AH21 -> 9901.11 | K11: ='Data Summary'!AH25 -> 21495.42 | M11: =IFERROR('Data Summary'!AH15/'Data Summary'!AH13,0) -> 0.094933882 | N11: =IFERROR(D11/C11,0) -> 3.4723093
C12: =TEXT('Data Summary'!AH8,"MMM YYYY") -> Sep 2025 | D12: =TEXT('Data Summary'!AH8,"MMM YYYY") -> Sep 2025 | E12: =TEXT('Data Summary'!AH8,"MMM YYYY") -> Sep 2025 | F12: =TEXT('Data Summary'!AH8,"MMM YYYY") -> Sep 2025 | H12: =TEXT('Data Summary'!AH8,"MMM YYYY") -> Sep 2025 | I12: =TEXT('Data Summary'!AH8,"MMM YYYY") -> Sep 2025 | J12: =TEXT('Data Summary'!AH8,"MMM YYYY") -> Sep 2025 | K12: =TEXT('Data Summary'!AH8,"MMM YYYY") -> Sep 2025 | M12: =TEXT('Data Summary'!AH8,"MMM YYYY") -> Sep 2025 | N12: =TEXT('Data Summary'!AH8,"MMM YYYY") -> Sep 2025
B50: Month | C50: =TEXT('Data Summary'!W8,"MMM YY") -> Oct 24 | D50: =TEXT('Data Summary'!X8,"MMM YY") -> Nov 24 | E50: =TEXT('Data Summary'!Y8,"MMM YY") -> Dec 24 | F50: =TEXT('Data Summary'!Z8,"MMM YY") -> Jan 25 | G50: =TEXT('Data Summary'!AA8,"MMM YY") -> Feb 25 | H50: =TEXT('Data Summary'!AB8,"MMM YY") -> Mar 25 | I50: =TEXT('Data Summary'!AC8,"MMM YY") -> Apr 25 | J50: =TEXT('Data Summary'!AD8,"MMM YY") -> May 25 | ... N50: =TEXT('Data Summary'!AH8,"MMM YY") -> Sep 25
B51: Revenue | C51: ='Data Summary'!W13 -> 51051 | D51: ='Data Summary'!X13 -> 53604 | E51: ='Data Summary'!Y13 -> 56284 | F51: ='Data Summary'!Z13 -> 59098.22 | G51: ='Data Summary'!AA13 -> 62053 | H51: ='Data Summary'!AB13 -> 65156 | I51: ='Data Summary'!AC13 -> 68414 | J51: ='Data Summary'!AD13 -> 71834 | ... N51: ='Data Summary'!AH13 -> 87314.98
B52: COGS | C52: ='Data Summary'!W15 -> 4846.33 | D52: ='Data Summary'!X15 -> 5089.33 | E52: ='Data Summary'!Y15 -> 5343 | F52: ='Data Summary'!Z15 -> 5610.42 | G52: ='Data Summary'!AA15 -> 5890 | H52: ='Data Summary'!AB15 -> 6185 | I52: ='Data Summary'!AC15 -> 6495 | J52: ='Data Summary'!AD15 -> 6820 | ... N52: ='Data Summary'!AH15 -> 8289.15
B54: Category | C54: Amount
B55: Marketing & Advertising | C55: ='Data Summary'!AH17 -> 91625.69
B56: Office & G&A | C56: ='Data Summary'!AH18 -> 90655.73
B57: Payroll | C57: ='Data Summary'!AH19 -> 81610
B58: Professional Services | C58: ='Data Summary'!AH20 -> 29392.09
B59: Travel & Entertainment | C59: ='Data Summary'!AH21 -> 9901.11
B61: Month | C61: =C50 -> Oct 24 | D61: =D50 -> Nov 24 | E61: =E50 -> Dec 24 | F61: =F50 -> Jan 25 | G61: =G50 -> Feb 25 | H61: =H50 -> Mar 25 | I61: =I50 -> Apr 25 | J61: =J50 -> May 25 | ... N61: =N50 -> Sep 25
B62: Cash | C62: ='Data Summary'!W29 -> 3066455.5 | D62: ='Data Summary'!X29 -> 2909186.5 | E62: ='Data Summary'!Y29 -> 2744982.5 | F62: ='Data Summary'!Z29 -> 2573511.5 | G62: ='Data Summary'!AA29 -> 2394437.5 | H62: ='Data Summary'!AB29 -> 2207358.5 | I62: ='Data Summary'!AC29 -> 2011881.5 | J62: ='Data Summary'!AD29 -> 1807588.5 | ... N62: ='Data Summary'!AH29 -> 893122.77
B64: Month | C64: =C50 -> Oct 24 | D64: =D50 -> Nov 24 | E64: =E50 -> Dec 24 | F64: =F50 -> Jan 25 | G64: =G50 -> Feb 25 | H64: =H50 -> Mar 25 | I64: =I50 -> Apr 25 | J64: =J50 -> May 25 | ... N64: =N50 -> Sep 25
B65: Revenue | C65: =C51 -> 51051 | D65: =D51 -> 53604 | E65: =E51 -> 56284 | F65: =F51 -> 59098.22 | G65: =G51 -> 62053 | H65: =H51 -> 65156 | I65: =I51 -> 68414 | J65: =J51 -> 71834 | ... N65: =N51 -> 87314.98
B66: Total Opex | C66: ='Data Summary'!W17+'Data Summary'!W18+'Data Summary'!W19+'Data Summary'!W20+'Data Summary'!W21 -> 177265.67 | D66: ='Data Summary'!X17+'Data Summary'!X18+'Data Summary'!X19+'Data Summary'!X20+'Data Summary'!X21 -> 186128.67 | E66: ='Data Summary'!Y17+'Data Summary'!Y18+'Data Summary'!Y19+'Data Summary'!Y20+'Data Summary'!Y21 -> 195434.5 | F66: ='Data Summary'!Z17+'Data Summary'!Z18+'Data Summary'!Z19+'Data Summary'!Z20+'Data Summary'!Z21 -> 205207.29 | G66: ='Data Summary'!AA17+'Data Summary'!AA18+'Data Summary'!AA19+'Data Summary'!AA20+'Data Summary'!AA21 -> 215468 | H66: ='Data Summary'!AB17+'Data Summary'!AB18+'Data Summary'!AB19+'Data Summary'!AB20+'Data Summary'!AB21 -> 226242 | I66: ='Data Summary'!AC17+'Data Summary'!AC18+'Data Summary'!AC19+'Data Summary'!AC20+'Data Summary'!AC21 -> 237553 | J66: ='Data Summary'!AD17+'Data Summary'!AD18+'Data Summary'!AD19+'Data Summary'!AD20+'Data Summary'!AD21 -> 249432 | ... N66: ='Data Summary'!AH17+'Data Summary'!AH18+'Data Summary'!AH19+'Data Summary'!AH20+'Data Summary'!AH21 -> 303184.62

Sheet AR Data
A1: Invoice # | B1: Customer | C1: Invoice Date | D1: Due Date | E1: Invoice Amount | F1: Amount Paid | G1: Balance | H1: Days Outstanding | I1: Aging Bucket | J1: Status | K1: Revenue (TTM) | M1: DSO TREND DATA
A2: INV-1001 | B2: Apex Technologies | C2: 46140 | D2: 46170 | E2: 187500 | F2: 0 | G2: =E2-F2 -> 187500 | H2: =IF(G2>0,TODAY()-C2,0) -> 38 | I2: =IF(G2=0,"Paid",IF(H2<=30,"Current",IF(H2<=60,"31-60",IF(H2<=90,"61-90","90+")))) -> 31-60 | J2: =IF(G2=0,"Paid",IF(H2<=30,"Current","Past Due")) -> Past Due | K2: 8450000 | M2: Month | N2: AR Balance | O2: Monthly Revenue | P2: DSO
A3: INV-1002 | B3: Apex Technologies | C3: 46110 | D3: 46140 | E3: 245000 | F3: 0 | G3: =E3-F3 -> 245000 | H3: =IF(G3>0,TODAY()-C3,0) -> 68 | I3: =IF(G3=0,"Paid",IF(H3<=30,"Current",IF(H3<=60,"31-60",IF(H3<=90,"61-90","90+")))) -> 61-90 | J3: =IF(G3=0,"Paid",IF(H3<=30,"Current","Past Due")) -> Past Due | M3: Jun-25 | N3: 2850000 | O3: 685000 | P3: =N3/O3*30 -> 124.81752
A4: INV-1003 | B4: Apex Technologies | C4: 45990 | D4: 46020 | E4: 312000 | F4: 150000 | G4: =E4-F4 -> 162000 | H4: =IF(G4>0,TODAY()-C4,0) -> 188 | I4: =IF(G4=0,"Paid",IF(H4<=30,"Current",IF(H4<=60,"31-60",IF(H4<=90,"61-90","90+")))) -> 90+ | J4: =IF(G4=0,"Paid",IF(H4<=30,"Current","Past Due")) -> Past Due | M4: Jul-25 | N4: 2920000 | O4: 710000 | P4: =N4/O4*30 -> 123.38028 | Q4: 685000 | R4: =P4/Q4*30 -> 0.005403516
A5: INV-1004 | B5: BlueStar Logistics | C5: 46135 | D5: 46165 | E5: 156000 | F5: 0 | G5: =E5-F5 -> 156000 | H5: =IF(G5>0,TODAY()-C5,0) -> 43 | I5: =IF(G5=0,"Paid",IF(H5<=30,"Current",IF(H5<=60,"31-60",IF(H5<=90,"61-90","90+")))) -> 31-60 | J5: =IF(G5=0,"Paid",IF(H5<=30,"Current","Past Due")) -> Past Due | M5: Aug-25 | N5: 3150000 | O5: 720000 | P5: =N5/O5*30 -> 131.25 | Q5: 710000
A6: INV-1005 | B6: BlueStar Logistics | C6: 46020 | D6: 46050 | E6: 89500 | F6: 89500 | G6: =E6-F6 -> 0 | H6: =IF(G6>0,TODAY()-C6,0) -> 0 | I6: =IF(G6=0,"Paid",IF(H6<=30,"Current",IF(H6<=60,"31-60",IF(H6<=90,"61-90","90+")))) -> Paid | J6: =IF(G6=0,"Paid",IF(H6<=30,"Current","Past Due")) -> Paid | M6: Sep-25 | N6: 3380000 | O6: 695000 | P6: =N6/O6*30 -> 145.89928 | Q6: 720000
A7: INV-1006 | B7: BlueStar Logistics | C7: 45960 | D7: 45990 | E7: 210000 | F7: 100000 | G7: =E7-F7 -> 110000 | H7: =IF(G7>0,TODAY()-C7,0) -> 218 | I7: =IF(G7=0,"Paid",IF(H7<=30,"Current",IF(H7<=60,"31-60",IF(H7<=90,"61-90","90+")))) -> 90+ | J7: =IF(G7=0,"Paid",IF(H7<=30,"Current","Past Due")) -> Past Due | M7: Oct-25 | N7: 3050000 | O7: 730000 | P7: =N7/O7*30 -> 125.34247 | Q7: 695000
A8: INV-1007 | B8: Cascade Industries | C8: 46143 | D8: 46173 | E8: 425000 | F8: 0 | G8: =E8-F8 -> 425000 | H8: =IF(G8>0,TODAY()-C8,0) -> 35 | I8: =IF(G8=0,"Paid",IF(H8<=30,"Current",IF(H8<=60,"31-60",IF(H8<=90,"61-90","90+")))) -> 31-60 | J8: =IF(G8=0,"Paid",IF(H8<=30,"Current","Past Due")) -> Past Due | M8: Nov-25 | N8: 3210000 | O8: 745000 | P8: =N8/O8*30 -> 129.26174 | Q8: 730000
A9: INV-1008 | B9: Cascade Industries | C9: 46105 | D9: 46135 | E9: 178000 | F9: 0 | G9: =E9-F9 -> 178000 | H9: =IF(G9>0,TODAY()-C9,0) -> 73 | I9: =IF(G9=0,"Paid",IF(H9<=30,"Current",IF(H9<=60,"31-60",IF(H9<=90,"61-90","90+")))) -> 61-90 | J9: =IF(G9=0,"Paid",IF(H9<=30,"Current","Past Due")) -> Past Due | M9: Dec-25 | N9: 3540000 | O9: 760000 | P9: =N9/O9*30 -> 139.73684 | Q9: 745000
A10: INV-1009 | B10: Cascade Industries | C10: 45930 | D10: 45960 | E10: 95000 | F10: 0 | G10: =E10-F10 -> 95000 | H10: =IF(G10>0,TODAY()-C10,0) -> 248 | I10: =IF(G10=0,"Paid",IF(H10<=30,"Current",IF(H10<=60,"31-60",IF(H10<=90,"61-90","90+")))) -> 90+ | J10: =IF(G10=0,"Paid",IF(H10<=30,"Current","Past Due")) -> Past Due | M10: Jan-26 | N10: 3680000 | O10: 700000 | P10: =N10/O10*30 -> 157.71429 | Q10: 760000
A11: INV-1010 | B11: Delta Partners | C11: 46138 | D11: 46168 | E11: 67500 | F11: 0 | G11: =E11-F11 -> 67500 | H11: =IF(G11>0,TODAY()-C11,0) -> 40 | I11: =IF(G11=0,"Paid",IF(H11<=30,"Current",IF(H11<=60,"31-60",IF(H11<=90,"61-90","90+")))) -> 31-60 | J11: =IF(G11=0,"Paid",IF(H11<=30,"Current","Past Due")) -> Past Due | M11: Feb-26 | N11: 3420000 | O11: 690000 | P11: =N11/O11*30 -> 148.69565 | Q11: 700000
A12: INV-1011 | B12: Delta Partners | C12: 46115 | D12: 46145 | E12: 134000 | F12: 0 | G12: =E12-F12 -> 134000 | H12: =IF(G12>0,TODAY()-C12,0) -> 63 | I12: =IF(G12=0,"Paid",IF(H12<=30,"Current",IF(H12<=60,"31-60",IF(H12<=90,"61-90","90+")))) -> 61-90 | J12: =IF(G12=0,"Paid",IF(H12<=30,"Current","Past Due")) -> Past Due | M12: Mar-26 | N12: 3750000 | O12: 715000 | P12: =N12/O12*30 -> 157.34266 | Q12: 690000
A13: INV-1012 | B13: Evergreen Health | C13: 46130 | D13: 46160 | E13: 298000 | F13: 0 | G13: =E13-F13 -> 298000 | H13: =IF(G13>0,TODAY()-C13,0) -> 48 | I13: =IF(G13=0,"Paid",IF(H13<=30,"Current",IF(H13<=60,"31-60",IF(H13<=90,"61-90","90+")))) -> 31-60 | J13: =IF(G13=0,"Paid",IF(H13<=30,"Current","Past Due")) -> Past Due | M13: Apr-26 | N13: 3890000 | O13: 740000 | P13: =N13/O13*30 -> 157.7027 | Q13: 715000
A14: INV-1013 | B14: Evergreen Health | C14: 46010 | D14: 46040 | E14: 185000 | F14: 0 | G14: =E14-F14 -> 185000 | H14: =IF(G14>0,TODAY()-C14,0) -> 168 | I14: =IF(G14=0,"Paid",IF(H14<=30,"Current",IF(H14<=60,"31-60",IF(H14<=90,"61-90","90+")))) -> 90+ | J14: =IF(G14=0,"Paid",IF(H14<=30,"Current","Past Due")) -> Past Due | M14: May-26 | N14: =SUMIF(J2:J35,"<>Paid",G2:G35) -> 5495500 | O14: 725000 | P14: =N14/O14*30 -> 227.4 | Q14: 740000
A15: INV-1014 | B15: Evergreen Health | C15: 45920 | D15: 45950 | E15: 142000 | F15: 50000 | G15: =E15-F15 -> 92000 | H15: =IF(G15>0,TODAY()-C15,0) -> 258 | I15: =IF(G15=0,"Paid",IF(H15<=30,"Current",IF(H15<=60,"31-60",IF(H15<=90,"61-90","90+")))) -> 90+ | J15: =IF(G15=0,"Paid",IF(H15<=30,"Current","Past Due")) -> Past Due | P15: =SUMIF(L3:L36,"<>Paid",I3:I36) -> 0 | Q15: 725000
A16: INV-1015 | B16: Frontier Software | C16: 46118 | D16: 46148 | E16: 78000 | F16: 0 | G16: =E16-F16 -> 78000 | H16: =IF(G16>0,TODAY()-C16,0) -> 60 | I16: =IF(G16=0,"Paid",IF(H16<=30,"Current",IF(H16<=60,"31-60",IF(H16<=90,"61-90","90+")))) -> 31-60 | J16: =IF(G16=0,"Paid",IF(H16<=30,"Current","Past Due")) -> Past Due
A17: INV-1016 | B17: Frontier Software | C17: 46000 | D17: 46030 | E17: 112000 | F17: 112000 | G17: =E17-F17 -> 0 | H17: =IF(G17>0,TODAY()-C17,0) -> 0 | I17: =IF(G17=0,"Paid",IF(H17<=30,"Current",IF(H17<=60,"31-60",IF(H17<=90,"61-90","90+")))) -> Paid | J17: =IF(G17=0,"Paid",IF(H17<=30,"Current","Past Due")) -> Paid
A18: INV-1017 | B18: GlobalTech Solutions | C18: 46142 | D18: 46172 | E18: 520000 | F18: 0 | G18: =E18-F18 -> 520000 | H18: =IF(G18>0,TODAY()-C18,0) -> 36 | I18: =IF(G18=0,"Paid",IF(H18<=30,"Current",IF(H18<=60,"31-60",IF(H18<=90,"61-90","90+")))) -> 31-60 | J18: =IF(G18=0,"Paid",IF(H18<=30,"Current","Past Due")) -> Past Due
A19: INV-1018 | B19: GlobalTech Solutions | C19: 46108 | D19: 46138 | E19: 345000 | F19: 200000 | G19: =E19-F19 -> 145000 | H19: =IF(G19>0,TODAY()-C19,0) -> 70 | I19: =IF(G19=0,"Paid",IF(H19<=30,"Current",IF(H19<=60,"31-60",IF(H19<=90,"61-90","90+")))) -> 61-90 | J19: =IF(G19=0,"Paid",IF(H19<=30,"Current","Past Due")) -> Past Due
A20: INV-1019 | B20: GlobalTech Solutions | C20: 45940 | D20: 45970 | E20: 275000 | F20: 275000 | G20: =E20-F20 -> 0 | H20: =IF(G20>0,TODAY()-C20,0) -> 0 | I20: =IF(G20=0,"Paid",IF(H20<=30,"Current",IF(H20<=60,"31-60",IF(H20<=90,"61-90","90+")))) -> Paid | J20: =IF(G20=0,"Paid",IF(H20<=30,"Current","Past Due")) -> Paid
A21: INV-1020 | B21: Harbor Financial | C21: 46112 | D21: 46142 | E21: 198000 | F21: 0 | G21: =E21-F21 -> 198000 | H21: =IF(G21>0,TODAY()-C21,0) -> 66 | I21: =IF(G21=0,"Paid",IF(H21<=30,"Current",IF(H21<=60,"31-60",IF(H21<=90,"61-90","90+")))) -> 61-90 | J21: =IF(G21=0,"Paid",IF(H21<=30,"Current","Past Due")) -> Past Due
A22: INV-1021 | B22: Harbor Financial | C22: 45985 | D22: 46015 | E22: 87000 | F22: 87000 | G22: =E22-F22 -> 0 | H22: =IF(G22>0,TODAY()-C22,0) -> 0 | I22: =IF(G22=0,"Paid",IF(H22<=30,"Current",IF(H22<=60,"31-60",IF(H22<=90,"61-90","90+")))) -> Paid | J22: =IF(G22=0,"Paid",IF(H22<=30,"Current","Past Due")) -> Paid
A23: INV-1022 | B23: Ironclad Manufacturing | C23: 46137 | D23: 46167 | E23: 445000 | F23: 0 | G23: =E23-F23 -> 445000 | H23: =IF(G23>0,TODAY()-C23,0) -> 41 | I23: =IF(G23=0,"Paid",IF(H23<=30,"Current",IF(H23<=60,"31-60",IF(H23<=90,"61-90","90+")))) -> 31-60 | J23: =IF(G23=0,"Paid",IF(H23<=30,"Current","Past Due")) -> Past Due
A24: INV-1023 | B24: Ironclad Manufacturing | C24: 46095 | D24: 46125 | E24: 367000 | F24: 0 | G24: =E24-F24 -> 367000 | H24: =IF(G24>0,TODAY()-C24,0) -> 83 | I24: =IF(G24=0,"Paid",IF(H24<=30,"Current",IF(H24<=60,"31-60",IF(H24<=90,"61-90","90+")))) -> 61-90 | J24: =IF(G24=0,"Paid",IF(H24<=30,"Current","Past Due")) -> Past Due
A25: INV-1024 | B25: Ironclad Manufacturing | C25: 45910 | D25: 45940 | E25: 290000 | F25: 190000 | G25: =E25-F25 -> 100000 | H25: =IF(G25>0,TODAY()-C25,0) -> 268 | I25: =IF(G25=0,"Paid",IF(H25<=30,"Current",IF(H25<=60,"31-60",IF(H25<=90,"61-90","90+")))) -> 90+ | J25: =IF(G25=0,"Paid",IF(H25<=30,"Current","Past Due")) -> Past Due
A26: INV-1025 | B26: Jetstream Aviation | C26: 46133 | D26: 46163 | E26: 156000 | F26: 0 | G26: =E26-F26 -> 156000 | H26: =IF(G26>0,TODAY()-C26,0) -> 45 | I26: =IF(G26=0,"Paid",IF(H26<=30,"Current",IF(H26<=60,"31-60",IF(H26<=90,"61-90","90+")))) -> 31-60 | J26: =IF(G26=0,"Paid",IF(H26<=30,"Current","Past Due")) -> Past Due
A27: INV-1027 | B27: Jetstream Aviation | C27: 45950 | D27: 45980 | E27: 223000 | F27: 100000 | G27: =E27-F27 -> 123000 | H27: =IF(G27>0,TODAY()-C27,0) -> 228 | I27: =IF(G27=0,"Paid",IF(H27<=30,"Current",IF(H27<=60,"31-60",IF(H27<=90,"61-90","90+")))) -> 90+ | J27: =IF(G27=0,"Paid",IF(H27<=30,"Current","Past Due")) -> Past Due
... A35: INV-1035 | B35: Nexus Consulting | C35: 45880 | D35: 45910 | E35: 195000 | F35: 0 | G35: =E35-F35 -> 195000 | H35: =IF(G35>0,TODAY()-C35,0) -> 298 | I35: =IF(G35=0,"Paid",IF(H35<=30,"Current",IF(H35<=60,"31-60",IF(H35<=90,"61-90","90+")))) -> 90+ | J35: =IF(G35=0,"Paid",IF(H35<=30,"Current","Past Due")) -> Past Due

Sheet Financial Summary
A1: __FIND_ME__
C2: Nimbus Cloud Solutions
C4: FINANCIAL SUMMARY
E5: 45292 | F5: 45323 | G5: 45352 | H5: 45383 | I5: 45413 | J5: 45444 | K5: 45474 | L5: 45505 | M5: 45536 | N5: 45566 | O5: 45597 | P5: 45627 | Q5: 45658 | R5: 45689 | S5: 45717 | T5: 45748 | U5: 45778 | V5: 45809 | W5: 45839 | X5: 45870 | Y5: 45901 | AA5: Q1 2024 | AB5: Q2 2024 | AC5: Q3 2024 | AD5: Q4 2024 | AE5: Q1 2025 | AF5: Q2 2025 | AG5: Q3 2025 | AI5: FY 2024 | AK5: YTD 2025 | AL5: TTM
E6: Monthly | F6: Monthly | G6: Monthly | H6: Monthly | I6: Monthly | J6: Monthly | K6: Monthly | L6: Monthly | M6: Monthly | N6: Monthly | O6: Monthly | P6: Monthly | Q6: Monthly | R6: Monthly | S6: Monthly | T6: Monthly | U6: Monthly | V6: Monthly | W6: Monthly | X6: Monthly | Y6: Monthly | AA6: Quarterly | AB6: Quarterly | AC6: Quarterly | AD6: Quarterly | AE6: Quarterly | AF6: Quarterly | AG6: Quarterly | AI6: Annual | AK6: Year-to-Date | AL6: Trailing 12 Mo.
B8: PROFIT & LOSS
C10: Revenue | E10: ='Data Summary'!N13 -> 48456.5 | F10: ='Data Summary'!O13 -> 42000 | G10: ='Data Summary'!P13 -> 50879.5 | H10: ='Data Summary'!Q13 -> 44100 | I10: ='Data Summary'!R13 -> 53424 | J10: ='Data Summary'!S13 -> 46305 | K10: ='Data Summary'!T13 -> 48620 | L10: ='Data Summary'!U13 -> 48620 | ... Y10: ='Data Summary'!AH13 -> 87314.98 | AA10: =SUM(E10:G10) -> 141336 | AB10: =SUM(H10:J10) -> 143829 | AC10: =SUM(K10:M10) -> 148291 | AD10: =SUM(N10:P10) -> 160939 | AE10: =SUM(Q10:S10) -> 186307.22 | AF10: =SUM(T10:V10) -> 224373.97 | AG10: =SUM(W10:Y10) -> 249669.37 | AI10: =SUM(E10:P10) -> 594395 | AK10: =SUM(Q10:Y10) -> 660350.56 | AL10: =SUM(N10:Y10) -> 821289.56
C11: Total Revenue | E11: =E10 -> 48456.5 | F11: =F10 -> 42000 | G11: =G10 -> 50879.5 | H11: =H10 -> 44100 | I11: =I10 -> 53424 | J11: =J10 -> 46305 | K11: =K10 -> 48620 | L11: =L10 -> 48620 | ... Y11: =Y10 -> 87314.98 | AA11: =AA10 -> 141336 | AB11: =AB10 -> 143829 | AC11: =AC10 -> 148291 | AD11: =AD10 -> 160939 | AE11: =AE10 -> 186307.22 | AF11: =AF10 -> 224373.97 | AG11: =AG10 -> 249669.37 | AI11: =AI10 -> 594395 | AK11: =AK10 -> 660350.56 | AL11: =AL10 -> 821289.56
C13: Cost of Goods Sold | E13: ='Data Summary'!N15+'Data Summary'!N16 -> 3599 | F13: ='Data Summary'!O15+'Data Summary'!O16 -> 3988 | G13: ='Data Summary'!P15+'Data Summary'!P16 -> 3779 | H13: ='Data Summary'!Q15+'Data Summary'!Q16 -> 4186.5 | I13: ='Data Summary'!R15+'Data Summary'!R16 -> 3968.5 | J13: ='Data Summary'!S15+'Data Summary'!S16 -> 4396.5 | K13: ='Data Summary'!T15+'Data Summary'!T16 -> 4615 | L13: ='Data Summary'!U15+'Data Summary'!U16 -> 4614.5 | ... Y13: ='Data Summary'!AH15+'Data Summary'!AH16 -> 8289.15 | AA13: =SUM(E13:G13) -> 11366 | AB13: =SUM(H13:J13) -> 12551.5 | AC13: =SUM(K13:M13) -> 14075.5 | AD13: =SUM(N13:P13) -> 15278.66 | AE13: =SUM(Q13:S13) -> 17685.42 | AF13: =SUM(T13:V13) -> 20775.48 | AG13: =SUM(W13:Y13) -> 22702.08 | AI13: =SUM(E13:P13) -> 53271.66 | AK13: =SUM(Q13:Y13) -> 61162.98 | AL13: =SUM(N13:Y13) -> 76441.64
C14: Gross Profit | E14: =E11-E13 -> 44857.5 | F14: =F11-F13 -> 38012 | G14: =G11-G13 -> 47100.5 | H14: =H11-H13 -> 39913.5 | I14: =I11-I13 -> 49455.5 | J14: =J11-J13 -> 41908.5 | K14: =K11-K13 -> 44005 | L14: =L11-L13 -> 44005.5 | ... Y14: =Y11-Y13 -> 79025.83 | AA14: =AA11-AA13 -> 129970 | AB14: =AB11-AB13 -> 131277.5 | AC14: =AC11-AC13 -> 134215.5 | AD14: =AD11-AD13 -> 145660.34 | AE14: =AE11-AE13 -> 168621.8 | AF14: =AF11-AF13 -> 203598.49 | AG14: =AG11-AG13 -> 226967.29 | AI14: =AI11-AI13 -> 541123.34 | AK14: =AK11-AK13 -> 599187.58 | AL14: =AL11-AL13 -> 744847.92
C16: Marketing & Advertising | E16: ='Data Summary'!N17 -> 27987 | F16: ='Data Summary'!O17 -> 44074 | G16: ='Data Summary'!P17 -> 29386 | H16: ='Data Summary'!Q17 -> 46277 | I16: ='Data Summary'!R17 -> 30855 | J16: ='Data Summary'!S17 -> 48591 | K16: ='Data Summary'!T17 -> 51020 | L16: ='Data Summary'!U17 -> 51020 | ... Y16: ='Data Summary'!AH17 -> 91625.69 | AA16: =SUM(E16:G16) -> 101447 | AB16: =SUM(H16:J16) -> 125723 | AC16: =SUM(K16:M16) -> 155612 | AD16: =SUM(N16:P16) -> 168885 | AE16: =SUM(Q16:S16) -> 195505.87 | AF16: =SUM(T16:V16) -> 226320.72 | AG16: =SUM(W16:Y16) -> 261995.46 | AI16: =SUM(E16:P16) -> 551667 | AK16: =SUM(Q16:Y16) -> 683822.05 | AL16: =SUM(N16:Y16) -> 852707.05
C17: Office & Other G&A | E17: ='Data Summary'!N18 -> 34792.5 | F17: ='Data Summary'!O18 -> 43606 | G17: ='Data Summary'!P18 -> 36531 | H17: ='Data Summary'!Q18 -> 45786 | I17: ='Data Summary'!R18 -> 38358 | J17: ='Data Summary'!S18 -> 48076.5 | K17: ='Data Summary'!T18 -> 50480 | L17: ='Data Summary'!U18 -> 50479.5 | ... Y17: ='Data Summary'!AH18 -> 90655.73 | AA17: =SUM(E17:G17) -> 114929.5 | AB17: =SUM(H17:J17) -> 132220.5 | AC17: =SUM(K17:M17) -> 153963.5 | AD17: =SUM(N17:P17) -> 167093.16 | AE17: =SUM(Q17:S17) -> 193436.37 | AF17: =SUM(T17:V17) -> 224926.82 | AG17: =SUM(W17:Y17) -> 259221.93 | AI17: =SUM(E17:P17) -> 568206.66 | AK17: =SUM(Q17:Y17) -> 677585.12 | AL17: =SUM(N17:Y17) -> 844678.28
C18: Payroll | E18: ='Data Summary'!N19 -> 22188 | F18: ='Data Summary'!O19 -> 39256 | G18: ='Data Summary'!P19 -> 23297 | H18: ='Data Summary'!Q19 -> 41219 | I18: ='Data Summary'!R19 -> 24463 | J18: ='Data Summary'!S19 -> 43279 | K18: ='Data Summary'!T19 -> 45443 | L18: ='Data Summary'!U19 -> 45443 | ... Y18: ='Data Summary'!AH19 -> 81610 | AA18: =SUM(E18:G18) -> 84741 | AB18: =SUM(H18:J18) -> 108961 | AC18: =SUM(K18:M18) -> 138602 | AD18: =SUM(N18:P18) -> 150425.68 | AE18: =SUM(Q18:S18) -> 174134.87 | AF18: =SUM(T18:V18) -> 201582.84 | AG18: =SUM(W18:Y18) -> 233356.49 | AI18: =SUM(E18:P18) -> 482729.68 | AK18: =SUM(Q18:Y18) -> 609074.2 | AL18: =SUM(N18:Y18) -> 759499.88
C19: Professional Services | E19: ='Data Summary'!N20 -> 8168 | F19: ='Data Summary'!O20 -> 14138 | G19: ='Data Summary'!P20 -> 8577 | H19: ='Data Summary'!Q20 -> 14845 | I19: ='Data Summary'!R20 -> 9005 | J19: ='Data Summary'!S20 -> 15587 | K19: ='Data Summary'!T20 -> 16368 | L19: ='Data Summary'!U20 -> 16368 | ... Y19: ='Data Summary'!AH20 -> 29392.09 | AA19: =SUM(E19:G19) -> 30883 | AB19: =SUM(H19:J19) -> 39437 | AC19: =SUM(K19:M19) -> 49920 | AD19: =SUM(N19:P19) -> 54175 | AE19: =SUM(Q19:S19) -> 62714.72 | AF19: =SUM(T19:V19) -> 72600 | AG19: =SUM(W19:Y19) -> 84044.04 | AI19: =SUM(E19:P19) -> 174415 | AK19: =SUM(Q19:Y19) -> 219358.76 | AL19: =SUM(N19:Y19) -> 273533.76
C20: Travel & Entertainment | E20: ='Data Summary'!N21 -> 3031 | F20: ='Data Summary'!O21 -> 4762 | G20: ='Data Summary'!P21 -> 3183 | H20: ='Data Summary'!Q21 -> 5001 | I20: ='Data Summary'!R21 -> 3341 | J20: ='Data Summary'!S21 -> 5251 | K20: ='Data Summary'!T21 -> 5514 | L20: ='Data Summary'!U21 -> 5514 | ... Y20: ='Data Summary'!AH21 -> 9901.11 | AA20: =SUM(E20:G20) -> 10976 | AB20: =SUM(H20:J20) -> 13593 | AC20: =SUM(K20:M20) -> 16817 | AD20: =SUM(N20:P20) -> 18250 | AE20: =SUM(Q20:S20) -> 21125.46 | AF20: =SUM(T20:V20) -> 24456.9 | AG20: =SUM(W20:Y20) -> 28311.36 | AI20: =SUM(E20:P20) -> 59636 | AK20: =SUM(Q20:Y20) -> 73893.72 | AL20: =SUM(N20:Y20) -> 92143.72
C21: Total Operating Expenses | E21: =SUM(E16:E20) -> 96166.5 | F21: =SUM(F16:F20) -> 145836 | G21: =SUM(G16:G20) -> 100974 | H21: =SUM(H16:H20) -> 153128 | I21: =SUM(I16:I20) -> 106022 | J21: =SUM(J16:J20) -> 160784.5 | K21: =SUM(K16:K20) -> 168825 | L21: =SUM(L16:L20) -> 168824.5 | ... Y21: =SUM(Y16:Y20) -> 303184.62 | AA21: =SUM(AA16:AA20) -> 342976.5 | AB21: =SUM(AB16:AB20) -> 419934.5 | AC21: =SUM(AC16:AC20) -> 514914.5 | AD21: =SUM(AD16:AD20) -> 558828.84 | AE21: =SUM(AE16:AE20) -> 646917.29 | AF21: =SUM(AF16:AF20) -> 749887.28 | AG21: =SUM(AG16:AG20) -> 866929.28 | AI21: =SUM(AI16:AI20) -> 1836654.3 | AK21: =SUM(AK16:AK20) -> 2263733.9 | AL21: =SUM(AL16:AL20) -> 2822562.7
C23: Operating Income (Loss) | E23: =E14-E21 -> -51309 | F23: =F14-F21 -> -107824 | G23: =G14-G21 -> -53873.5 | H23: =H14-H21 -> -113214.5 | I23: =I14-I21 -> -56566.5 | J23: =J14-J21 -> -118876 | K23: =K14-K21 -> -124820 | L23: =L14-L21 -> -124819 | ... Y23: =Y14-Y21 -> -224158.79 | AA23: =AA14-AA21 -> -213006.5 | AB23: =AB14-AB21 -> -288657 | AC23: =AC14-AC21 -> -380699 | AD23: =AD14-AD21 -> -413168.5 | AE23: =AE14-AE21 -> -478295.49 | AF23: =AF14-AF21 -> -546288.79 | AG23: =AG14-AG21 -> -639961.99 | AI23: =AI14-AI21 -> -1295531 | AK23: =AK14-AK21 -> -1664546.3 | AL23: =AL14-AL21 -> -2077714.8
C25: Other Income | E25: ='Data Summary'!N22 -> 0 | F25: ='Data Summary'!O22 -> 0 | G25: ='Data Summary'!P22 -> 0 | H25: ='Data Summary'!Q22 -> 0 | I25: ='Data Summary'!R22 -> 0 | J25: ='Data Summary'!S22 -> 0 | K25: ='Data Summary'!T22 -> 0 | L25: ='Data Summary'!U22 -> 0 | ... Y25: ='Data Summary'!AH22 -> 0 | AA25: =SUM(E25:G25) -> 0 | AB25: =SUM(H25:J25) -> 0 | AC25: =SUM(K25:M25) -> 0 | AD25: =SUM(N25:P25) -> 0 | AE25: =SUM(Q25:S25) -> 0 | AF25: =SUM(T25:V25) -> 0 | AG25: =SUM(W25:Y25) -> 0 | AI25: =SUM(E25:P25) -> 0 | AK25: =SUM(Q25:Y25) -> 0 | AL25: =SUM(N25:Y25) -> 0
C26: Depreciation & Amortization | E26: ='Data Summary'!N23 -> 0 | F26: ='Data Summary'!O23 -> 0 | G26: ='Data Summary'!P23 -> 0 | H26: ='Data Summary'!Q23 -> 0 | I26: ='Data Summary'!R23 -> 0 | J26: ='Data Summary'!S23 -> 0 | K26: ='Data Summary'!T23 -> 0 | L26: ='Data Summary'!U23 -> 0 | ... Y26: ='Data Summary'!AH23 -> 0 | AA26: =SUM(E26:G26) -> 0 | AB26: =SUM(H26:J26) -> 0 | AC26: =SUM(K26:M26) -> 0 | AD26: =SUM(N26:P26) -> 0 | AE26: =SUM(Q26:S26) -> 0 | AF26: =SUM(T26:V26) -> 0 | AG26: =SUM(W26:Y26) -> 0 | AI26: =SUM(E26:P26) -> 0 | AK26: =SUM(Q26:Y26) -> 0 | AL26: =SUM(N26:Y26) -> 0
C27: Other Expenses | E27: ='Data Summary'!N24+'Data Summary'!N25 -> 21495.5 | F27: ='Data Summary'!O24+'Data Summary'!O25 -> 21496 | G27: ='Data Summary'!P24+'Data Summary'!P25 -> 21496 | H27: ='Data Summary'!Q24+'Data Summary'!Q25 -> 21496 | I27: ='Data Summary'!R24+'Data Summary'!R25 -> 21496 | J27: ='Data Summary'!S24+'Data Summary'!S25 -> 21496 | K27: ='Data Summary'!T24+'Data Summary'!T25 -> 21496 | L27: ='Data Summary'!U24+'Data Summary'!U25 -> 21496 | ... Y27: ='Data Summary'!AH24+'Data Summary'!AH25 -> 21495.42 | AA27: =SUM(E27:G27) -> 64487.5 | AB27: =SUM(H27:J27) -> 64488 | AC27: =SUM(K27:M27) -> 64488 | AD27: =SUM(N27:P27) -> 64488 | AE27: =SUM(Q27:S27) -> 64486.74 | AF27: =SUM(T27:V27) -> 64486.74 | AG27: =SUM(W27:Y27) -> 64486.26 | AI27: =SUM(E27:P27) -> 257951.5 | AK27: =SUM(Q27:Y27) -> 193459.74 | AL27: =SUM(N27:Y27) -> 257947.74
C29: Net Income (Loss) | E29: =E23+E25-E26-E27 -> -72804.5 | F29: =F23+F25-F26-F27 -> -129320 | G29: =G23+G25-G26-G27 -> -75369.5 | H29: =H23+H25-H26-H27 -> -134710.5 | I29: =I23+I25-I26-I27 -> -78062.5 | J29: =J23+J25-J26-J27 -> -140372 | K29: =K23+K25-K26-K27 -> -146316 | L29: =L23+L25-L26-L27 -> -146315 | ... Y29: =Y23+Y25-Y26-Y27 -> -245654.21 | AA29: =AA23+AA25-AA26-AA27 -> -277494 | AB29: =AB23+AB25-AB26-AB27 -> -353145 | AC29: =AC23+AC25-AC26-AC27 -> -445187 | AD29: =AD23+AD25-AD26-AD27 -> -477656.5 | AE29: =AE23+AE25-AE26-AE27 -> -542782.23 | AF29: =AF23+AF25-AF26-AF27 -> -610775.53 | AG29: =AG23+AG25-AG26-AG27 -> -704448.25 | AI29: =AI23+AI25-AI26-AI27 -> -1553482.5 | AK29: =AK23+AK25-AK26-AK27 -> -1858006 | AL29: =AL23+AL25-AL26-AL27 -> -2335662.5
B32: BALANCE SHEET
C34: Assets
C35: Cash | E35: {=INDEX('Data Summary'!N$8:N$38,29-7)} -> 4191288.5 | F35: {=INDEX('Data Summary'!O$8:O$38,29-7)} -> 4076334.5 | G35: {=INDEX('Data Summary'!P$8:P$38,29-7)} -> 4004840.5 | H35: {=INDEX('Data Summary'!Q$8:Q$38,29-7)} -> 3870793.5 | I35: {=INDEX('Data Summary'!R$8:R$38,29-7)} -> 3794994.5 | J35: {=INDEX('Data Summary'!S$8:S$38,29-7)} -> 3656851.5 | K35: {=INDEX('Data Summary'!T$8:T$38,29-7)} -> 3512188.5 | L35: {=INDEX('Data Summary'!U$8:U$38,29-7)} -> 3367871.5 | ... Y35: {=INDEX('Data Summary'!AH$8:AH$38,29-7)} -> 893122.77 | AA35: =G35 -> 4004840.5 | AB35: =J35 -> 3656851.5 | AC35: =M35 -> 3217220.5 | AD35: =P35 -> 2744982.5 | AE35: =S35 -> 2207358.5 | AF35: =V35 -> 1594040.1 | AG35: =Y35 -> 893122.77 | AI35: =P35 -> 2744982.5 | AK35: =Y35 -> 893122.77 | AL35: =Y35 -> 893122.77
C36: Accounts Receivable | E36: {=INDEX('Data Summary'!N$8:N$38,28-7)} -> 41127 | F36: {=INDEX('Data Summary'!O$8:O$38,28-7)} -> 41812 | G36: {=INDEX('Data Summary'!P$8:P$38,28-7)} -> 40987 | H36: {=INDEX('Data Summary'!Q$8:Q$38,28-7)} -> 43374 | I36: {=INDEX('Data Summary'!R$8:R$38,28-7)} -> 44161 | J36: {=INDEX('Data Summary'!S$8:S$38,28-7)} -> 44983 | K36: {=INDEX('Data Summary'!T$8:T$38,28-7)} -> 46381 | L36: {=INDEX('Data Summary'!U$8:U$38,28-7)} -> 47434 | ... Y36: {=INDEX('Data Summary'!AH$8:AH$38,28-7)} -> 73923.66 | AA36: =G36 -> 40987 | AB36: =J36 -> 44983 | AC36: =M36 -> 48580 | AD36: =P36 -> 52314 | AE36: =S36 -> 56307.77 | AF36: =V36 -> 69302.55 | AG36: =Y36 -> 73923.66 | AI36: =P36 -> 52314 | AK36: =Y36 -> 73923.66 | AL36: =Y36 -> 73923.66
C37: Current Assets | E37: {=INDEX('Data Summary'!N$8:N$38,30-7)} -> 26119.5 | F37: {=INDEX('Data Summary'!O$8:O$38,30-7)} -> 26119.5 | G37: {=INDEX('Data Summary'!P$8:P$38,30-7)} -> 26119.5 | H37: {=INDEX('Data Summary'!Q$8:Q$38,30-7)} -> 26119.5 | I37: {=INDEX('Data Summary'!R$8:R$38,30-7)} -> 26119.5 | J37: {=INDEX('Data Summary'!S$8:S$38,30-7)} -> 26119.5 | K37: {=INDEX('Data Summary'!T$8:T$38,30-7)} -> 26119.5 | L37: {=INDEX('Data Summary'!U$8:U$38,30-7)} -> 26119.5 | ... Y37: {=INDEX('Data Summary'!AH$8:AH$38,30-7)} -> 26819.5 | AA37: =G37 -> 26119.5 | AB37: =J37 -> 26119.5 | AC37: =M37 -> 26119.5 | AD37: =P37 -> 26119.5 | AE37: =S37 -> 26119.5 | AF37: =V37 -> 25819.5 | AG37: =Y37 -> 26819.5 | AI37: =P37 -> 26119.5 | AK37: =Y37 -> 26819.5 | AL37: =Y37 -> 26819.5
C38: Fixed Assets | E38: {=INDEX('Data Summary'!N$8:N$38,31-7)} -> 112416.5 | F38: {=INDEX('Data Summary'!O$8:O$38,31-7)} -> 97365.5 | G38: {=INDEX('Data Summary'!P$8:P$38,31-7)} -> 94315 | H38: {=INDEX('Data Summary'!Q$8:Q$38,31-7)} -> 91264.5 | I38: {=INDEX('Data Summary'!R$8:R$38,31-7)} -> 88214 | J38: {=INDEX('Data Summary'!S$8:S$38,31-7)} -> 85163 | K38: {=INDEX('Data Summary'!T$8:T$38,31-7)} -> 82112 | L38: {=INDEX('Data Summary'!U$8:U$38,31-7)} -> 79061 | ... Y38: {=INDEX('Data Summary'!AH$8:AH$38,31-7)} -> 39401.56 | AA38: =G38 -> 94315 | AB38: =J38 -> 85163 | AC38: =M38 -> 76010 | AD38: =P38 -> 66857.5 | AE38: =S38 -> 57705.52 | AF38: =V38 -> 48553.54 | AG38: =Y38 -> 39401.56 | AI38: =P38 -> 66857.5 | AK38: =Y38 -> 39401.56 | AL38: =Y38 -> 39401.56
C39: Other Current Assets | E39: {=INDEX('Data Summary'!N$8:N$38,32-7)} -> 0 | F39: {=INDEX('Data Summary'!O$8:O$38,32-7)} -> 0 | G39: {=INDEX('Data Summary'!P$8:P$38,32-7)} -> 0 | H39: {=INDEX('Data Summary'!Q$8:Q$38,32-7)} -> 0 | I39: {=INDEX('Data Summary'!R$8:R$38,32-7)} -> 0 | J39: {=INDEX('Data Summary'!S$8:S$38,32-7)} -> 0 | K39: {=INDEX('Data Summary'!T$8:T$38,32-7)} -> 0 | L39: {=INDEX('Data Summary'!U$8:U$38,32-7)} -> 0 | ... Y39: {=INDEX('Data Summary'!AH$8:AH$38,32-7)} -> 0 | AA39: =G39 -> 0 | AB39: =J39 -> 0 | AC39: =M39 -> 0 | AD39: =P39 -> 0 | AE39: =S39 -> 0 | AF39: =V39 -> 0 | AG39: =Y39 -> 0 | AI39: =P39 -> 0 | AK39: =Y39 -> 0 | AL39: =Y39 -> 0
C40: Total Assets | E40: =SUM(E35:E39) -> 4370951.5 | F40: =SUM(F35:F39) -> 4241631.5 | G40: =SUM(G35:G39) -> 4166262 | H40: =SUM(H35:H39) -> 4031551.5 | I40: =SUM(I35:I39) -> 3953489 | J40: =SUM(J35:J39) -> 3813117 | K40: =SUM(K35:K39) -> 3666801 | L40: =SUM(L35:L39) -> 3520486 | ... Y40: =SUM(Y35:Y39) -> 1033267.5 | AA40: =SUM(AA35:AA39) -> 4166262 | AB40: =SUM(AB35:AB39) -> 3813117 | AC40: =SUM(AC35:AC39) -> 3367930 | AD40: =SUM(AD35:AD39) -> 2890273.5 | AE40: =SUM(AE35:AE39) -> 2347491.3 | AF40: =SUM(AF35:AF39) -> 1737715.7 | AG40: =SUM(AG35:AG39) -> 1033267.5 | AI40: =SUM(AI35:AI39) -> 2890273.5 | AK40: =SUM(AK35:AK39) -> 1033267.5 | AL40: =SUM(AL35:AL39) -> 1033267.5
C42: Liabilities
C43: Accounts Payable | E43: {=INDEX('Data Summary'!N$8:N$38,33-7)} -> 55349.5 | F43: {=INDEX('Data Summary'!O$8:O$38,33-7)} -> 55349.5 | G43: {=INDEX('Data Summary'!P$8:P$38,33-7)} -> 55349.5 | H43: {=INDEX('Data Summary'!Q$8:Q$38,33-7)} -> 55349.5 | I43: {=INDEX('Data Summary'!R$8:R$38,33-7)} -> 55349.5 | J43: {=INDEX('Data Summary'!S$8:S$38,33-7)} -> 55349.5 | K43: {=INDEX('Data Summary'!T$8:T$38,33-7)} -> 55349.5 | L43: {=INDEX('Data Summary'!U$8:U$38,33-7)} -> 55349.5 | ... Y43: {=INDEX('Data Summary'!AH$8:AH$38,33-7)} -> 56349.5 | AA43: =G43 -> 55349.5 | AB43: =J43 -> 55349.5 | AC43: =M43 -> 55349.5 | AD43: =P43 -> 55349.5 | AE43: =S43 -> 55349.5 | AF43: =V43 -> 56349.5 | AG43: =Y43 -> 56349.5 | AI43: =P43 -> 55349.5 | AK43: =Y43 -> 56349.5 | AL43: =Y43 -> 56349.5
C44: Current Liabilities | E44: {=INDEX('Data Summary'!N$8:N$38,34-7)} -> -4942 | F44: {=INDEX('Data Summary'!O$8:O$38,34-7)} -> -4942 | G44: {=INDEX('Data Summary'!P$8:P$38,34-7)} -> -4942 | H44: {=INDEX('Data Summary'!Q$8:Q$38,34-7)} -> -4942 | I44: {=INDEX('Data Summary'!R$8:R$38,34-7)} -> -4942 | J44: {=INDEX('Data Summary'!S$8:S$38,34-7)} -> -4942 | K44: {=INDEX('Data Summary'!T$8:T$38,34-7)} -> -4942 | L44: {=INDEX('Data Summary'!U$8:U$38,34-7)} -> -4942 | ... Y44: {=INDEX('Data Summary'!AH$8:AH$38,34-7)} -> -4942 | AA44: =G44 -> -4942 | AB44: =J44 -> -4942 | AC44: =M44 -> -4942 | AD44: =P44 -> -4942 | AE44: =S44 -> -4942 | AF44: =V44 -> -4942 | AG44: =Y44 -> -4942 | AI44: =P44 -> -4942 | AK44: =Y44 -> -4942 | AL44: =Y44 -> -4942
C45: Debt | E45: {=INDEX('Data Summary'!N$8:N$38,35-7)} -> 1530000 | F45: {=INDEX('Data Summary'!O$8:O$38,35-7)} -> 1530000 | G45: {=INDEX('Data Summary'!P$8:P$38,35-7)} -> 1530000 | H45: {=INDEX('Data Summary'!Q$8:Q$38,35-7)} -> 1530000 | I45: {=INDEX('Data Summary'!R$8:R$38,35-7)} -> 1530000 | J45: {=INDEX('Data Summary'!S$8:S$38,35-7)} -> 1530000 | K45: {=INDEX('Data Summary'!T$8:T$38,35-7)} -> 1530000 | L45: {=INDEX('Data Summary'!U$8:U$38,35-7)} -> 1530000 | ... Y45: {=INDEX('Data Summary'!AH$8:AH$38,35-7)} -> 1530000 | AA45: =G45 -> 1530000 | AB45: =J45 -> 1530000 | AC45: =M45 -> 1530000 | AD45: =P45 -> 1530000 | AE45: =S45 -> 1530000 | AF45: =V45 -> 1530000 | AG45: =Y45 -> 1530000 | AI45: =P45 -> 1530000 | AK45: =Y45 -> 1530000 | AL45: =Y45 -> 1530000
C46: Deferred Revenue | E46: {=INDEX('Data Summary'!N$8:N$38,36-7)} -> 23270 | F46: {=INDEX('Data Summary'!O$8:O$38,36-7)} -> 23270 | G46: {=INDEX('Data Summary'!P$8:P$38,36-7)} -> 23270 | H46: {=INDEX('Data Summary'!Q$8:Q$38,36-7)} -> 23270 | I46: {=INDEX('Data Summary'!R$8:R$38,36-7)} -> 23270 | J46: {=INDEX('Data Summary'!S$8:S$38,36-7)} -> 23270 | K46: {=INDEX('Data Summary'!T$8:T$38,36-7)} -> 23270 | L46: {=INDEX('Data Summary'!U$8:U$38,36-7)} -> 23270 | ... Y46: {=INDEX('Data Summary'!AH$8:AH$38,36-7)} -> 23270 | AA46: =G46 -> 23270 | AB46: =J46 -> 23270 | AC46: =M46 -> 23270 | AD46: =P46 -> 23270 | AE46: =S46 -> 23270 | AF46: =V46 -> 23270 | AG46: =Y46 -> 23270 | AI46: =P46 -> 23270 | AK46: =Y46 -> 23270 | AL46: =Y46 -> 23270
C47: Total Liabilities | E47: =SUM(E43:E46) -> 1603677.5 | F47: =SUM(F43:F46) -> 1603677.5 | G47: =SUM(G43:G46) -> 1603677.5 | H47: =SUM(H43:H46) -> 1603677.5 | I47: =SUM(I43:I46) -> 1603677.5 | J47: =SUM(J43:J46) -> 1603677.5 | K47: =SUM(K43:K46) -> 1603677.5 | L47: =SUM(L43:L46) -> 1603677.5 | ... Y47: =SUM(Y43:Y46) -> 1604677.5 | AA47: =SUM(AA43:AA46) -> 1603677.5 | AB47: =SUM(AB43:AB46) -> 1603677.5 | AC47: =SUM(AC43:AC46) -> 1603677.5 | AD47: =SUM(AD43:AD46) -> 1603677.5 | AE47: =SUM(AE43:AE46) -> 1603677.5 | AF47: =SUM(AF43:AF46) -> 1604677.5 | AG47: =SUM(AG43:AG46) -> 1604677.5 | AI47: =SUM(AI43:AI46) -> 1603677.5 | AK47: =SUM(AK43:AK46) -> 1604677.5 | AL47: =SUM(AL43:AL46) -> 1604677.5
C49: Equity
